<?xml version='1.0' encoding='utf-8'?>
<robot name="epuck">
  
  <gazebo>
    <plugin filename="libgazebo_ros_diff_drive.so" name="diff_drive">
      <ros>
        <namespace>/epuck</namespace>
      </ros>
      <update_rate>100.0</update_rate>
      <left_joint>left_wheel_joint</left_joint>
      <right_joint>right_wheel_joint</right_joint>
      <wheel_separation>0.05398</wheel_separation>
      <wheel_diameter>0.040</wheel_diameter>
      <max_wheel_torque>20</max_wheel_torque>
      <max_wheel_acceleration>1.0</max_wheel_acceleration>
      <publish_odom>true</publish_odom>
      <publish_odom_tf>true</publish_odom_tf>
      <publish_wheel_tf>true</publish_wheel_tf>
      <odometry_frame>odom</odometry_frame>
      <robot_base_frame>robot_footprint</robot_base_frame>
    </plugin>
  </gazebo>

  <gazebo reference="left_wheel">
    <mu1>0.5</mu1>
    <mu2>0.5</mu2>
    <kp>500000.0</kp>
    <kd>10.0</kd>
    <minDepth>0.001</minDepth>
    <maxVel>0.5</maxVel>
    <fdir1>1 0 0</fdir1>
  </gazebo>

  <gazebo reference="right_wheel">
    <mu1>0.5</mu1>
    <mu2>0.5</mu2>
    <kp>500000.0</kp>
    <kd>10.0</kd>
    <minDepth>0.001</minDepth>
    <maxVel>0.5</maxVel>
    <fdir1>1 0 0</fdir1>
  </gazebo>

  
  <gazebo reference="camera">
    <sensor name="camera_sensor" type="camera">
      <update_rate>30.0</update_rate>
      <camera name="camera">
        <horizontal_fov>1.3962634</horizontal_fov>
        <image>
          <width>800</width>
          <height>800</height>
          <format>R8G8B8</format>
        </image>
        <clip>
          <near>0.02</near>
          <far>300</far>
        </clip>
      </camera>
      <plugin name="camera_controller" filename="libgazebo_ros_camera.so">
        <ros>
          <namespace>/bocbot</namespace>
          <remapping>image_raw:=camera/image</remapping>
          <remapping>camera_info:=camera/image/camera_info</remapping>
        </ros>
        <frame_name>camera</frame_name>
      </plugin>
    </sensor>
  </gazebo>

  
  <gazebo reference="hokuyo">
    <sensor name="head_hokuyo_sensor" type="ray">
      <pose>0 0 0 0 0 0</pose>
      <visualize>false</visualize>
      <update_rate>40</update_rate>
      <ray>
        <scan>
          <horizontal>
            <samples>720</samples>
            <resolution>1</resolution>
            <min_angle>-1.570796</min_angle>
            <max_angle>1.570796</max_angle>
          </horizontal>
        </scan>
        <range>
          <min>0.10</min>
          <max>30.0</max>
          <resolution>0.01</resolution>
        </range>
        <noise>
          <type>gaussian</type>
          <mean>0.0</mean>
          <stddev>0.01</stddev>
        </noise>
      </ray>
      <plugin name="gazebo_ros_head_hokuyo_controller" filename="libgazebo_ros_ray_sensor.so">
        <ros>
          <namespace>/bocbot</namespace>
          <remapping>~/out:=scan</remapping>
        </ros>
        <output_type>sensor_msgs/LaserScan</output_type>
      </plugin>
    </sensor>
  </gazebo>

  <link name="robot_footprint" />
  <joint name="robot_footprint_joint" type="fixed">
    <origin rpy="0 0 0" xyz="0 0 0" />
    <parent link="robot_footprint" />
    <child link="chassis" />
  </joint>
  <link name="chassis">
    <pose>0 0 0.1 0 0 0</pose>
    <inertial>
      <mass value="0.063515" />
      <origin rpy=" 0 0 0" xyz="0.0 0 0" />
      <inertia ixx="0.1" ixy="0" ixz="0" iyy="0.1" iyz="0" izz="0.1" />
    </inertial>
    <collision name="collision">
      <origin rpy=" 0 0 0" xyz="0 0 0" />
      <geometry>
        <mesh filename="/home/romi-lab-2/project_ws/src/my_simulation/my_simulation/meshes/urdf/main_body.STL" />
      </geometry>
    </collision>
    <visual name="chassis_visual">
      <origin rpy=" 0 0 0" xyz="0 0 0" />
      <geometry>
        <mesh filename="/home/romi-lab-2/project_ws/src/my_simulation/my_simulation/meshes/urdf/main_body.STL" />
      </geometry>
    </visual>
  </link>
  <link name="left_wheel">
    <inertial>
      <mass value="0.0040981" />
      <origin rpy="0 0 0" xyz="-0.00048709 -3.5245E-18 2.4286E-17" />
      <inertia ixx="8.267E-07" ixy="-9.8761E-23" ixz="-8.6429E-13" iyy="4.304E-07" iyz="-2.3376E-22" izz="4.304E-07" />
    </inertial>
    <visual>
      <origin rpy=" 0 0 0" xyz="0.0 0 0" />
      <geometry>
        <mesh filename="/home/romi-lab-2/project_ws/src/my_simulation/my_simulation/meshes/urdf/left_wheel.STL" />
      </geometry>
    </visual>
    <collision>
      <origin rpy=" 0 0 0" xyz="0.0 0 0" />
      <geometry>
        <mesh filename="/home/romi-lab-2/project_ws/src/my_simulation/my_simulation/meshes/urdf/left_wheel.STL" />
      </geometry>
    </collision>
  </link>
  <link name="right_wheel">
    <inertial>
      <mass value="0.0038059" />
      <origin rpy=" 0 0 0" xyz="0.00065056 4.0415E-18 7.2858E-17" />
      <inertia ixx="8.2274E-07" ixy="-1.0753E-22" ixz="8.6429E-13" iyy="4.2585E-07" iyz="2.3307E-22" izz="4.2585E-07" />
    </inertial>
    <visual>
      <origin rpy="0 0 0" xyz="0.0 0 0" />
      <geometry>
        <mesh filename="/home/romi-lab-2/project_ws/src/my_simulation/my_simulation/meshes/urdf/right_wheel.STL" />
      </geometry>
    </visual>
    <collision>
      <origin rpy="0 0 0" xyz="0.0 0 0" />
      <geometry>
        <mesh filename="/home/romi-lab-2/project_ws/src/my_simulation/my_simulation/meshes/urdf/right_wheel.STL" />
      </geometry>
    </collision>
  </link>
  <link name="camera">
    <inertial>
      <mass value="0.01" />
      <origin rpy=" 0 0 0" xyz="0.005 0.005 0.05" />
      <inertia ixx="1e-6" ixy="0" ixz="0" iyy="1e-6" iyz="0" izz="1e-6" />
    </inertial>
    <visual name="camera_visual">
      <origin rpy="0 0 0" xyz="0 0 0" />
      <geometry>
        <box size="0.01 0.01 0.01" />
      </geometry>
    </visual>
    <collision name="camera_colision">
      <origin rpy="0 0 0" xyz="0 0 0" />
      <geometry>
        <box size="0.01 0.01 0.01" />
      </geometry>
    </collision>
  </link>
  <link name="hokuyo">
    <inertial>
      <mass value="1e-5" />
      <origin rpy=" 0 0 0" xyz="0 0 0" />
      <inertia ixx="1e-6" ixy="0" ixz="0" iyy="1e-6" iyz="0" izz="1e-6" />
    </inertial>
    <visual name="hokuyo_visual">
      <origin rpy="0 0 0" xyz="0 0 0" />
      <geometry>
        
        <box size="0.01 0.01 0.01" />
      </geometry>
    </visual>
    <collision name="hokuyo_colision">
      <origin rpy="0 0 0" xyz="0 0 0" />
      <geometry>
        <box size="0.01 0.01 0.01" />
      </geometry>
    </collision>
  </link>
  <joint name="left_wheel_joint" type="continuous">
    <origin rpy="0 0 0" xyz="0.0278 0 0.02" />
    <child link="left_wheel" />
    <parent link="chassis" />
    <axis rpy="0 0 0" xyz="1 0  0" />
    <limit effort="0.001" velocity="10" />
    
  </joint>
  <joint name="right_wheel_joint" type="continuous">
    <origin rpy="0 0 0" xyz="-0.0278 0 0.02" />
    <child link="right_wheel" />
    <parent link="chassis" />
    <axis rpy="0 0 0" xyz="1 0 0" />
    <limit effort="0.001" velocity="10" />
    
  </joint>
  <joint name="camera_joint" type="fixed">
    <origin rpy="0 0 0" xyz="0 0 0.07596" />
    <child link="camera" />
    <parent link="chassis" />
    <axis rpy="0 0 0" xyz="0 0 1" />
  </joint>
  <joint name="hokuyo_joint" type="fixed">
    <origin rpy="0 0 0" xyz="0 0 0.05596" />
    <child link="hokuyo" />
    <parent link="chassis" />
    <axis rpy="0 0 0" xyz="0 0 1" />
  </joint>
  <gazebo reference="chassis">
    <material>Gazebo/Blue</material>
  </gazebo>
  <gazebo reference="camera">
    <material>Gazebo/Red</material>
  </gazebo>
  <gazebo reference="hokuyo">
    <material>Gazebo/Black</material>
  </gazebo>
</robot>